[2024-07-13 19:55:14,250: INFO: server: Started server process [13368]]
[2024-07-13 19:55:14,251: INFO: on: Waiting for application startup.]
[2024-07-13 19:55:14,252: INFO: on: Application startup complete.]
[2024-07-13 19:55:14,253: INFO: server: Uvicorn running on http://0.0.0.0:8080 (Press CTRL+C to quit)]
[2024-07-13 20:04:00,957: INFO: common: yaml file: config\config.yaml loaded successfully]
[2024-07-13 20:04:00,960: INFO: common: yaml file: params.yaml loaded successfully]
[2024-07-13 20:04:00,963: INFO: common: created directory at: artifacts]
[2024-07-13 20:04:00,964: INFO: common: created directory at: artifacts/model_evaluation]
[2024-07-13 20:04:00,966: ERROR: h11_impl: Exception in ASGI application
]
Traceback (most recent call last):
  File "C:\Users\91769\AppData\Local\Programs\Python\Python312\Lib\site-packages\transformers\utils\hub.py", line 402, in cached_file
    resolved_file = hf_hub_download(
                    ^^^^^^^^^^^^^^^^
  File "C:\Users\91769\AppData\Local\Programs\Python\Python312\Lib\site-packages\huggingface_hub\utils\_validators.py", line 106, in _inner_fn
    validate_repo_id(arg_value)
  File "C:\Users\91769\AppData\Local\Programs\Python\Python312\Lib\site-packages\huggingface_hub\utils\_validators.py", line 154, in validate_repo_id
    raise HFValidationError(
huggingface_hub.errors.HFValidationError: Repo id must be in the form 'repo_name' or 'namespace/repo_name': 'artifacts/model_trainer/tokenizer'. Use `repo_type` argument if needed.

The above exception was the direct cause of the following exception:

Traceback (most recent call last):
  File "C:\Users\91769\AppData\Local\Programs\Python\Python312\Lib\site-packages\uvicorn\protocols\http\h11_impl.py", line 404, in run_asgi
    result = await app(  # type: ignore[func-returns-value]
             ^^^^^^^^^^^^^^^^^^^^^^^^^^^^^^^^^^^^^^^^^^^^^^
  File "C:\Users\91769\AppData\Local\Programs\Python\Python312\Lib\site-packages\uvicorn\middleware\proxy_headers.py", line 78, in __call__
    return await self.app(scope, receive, send)
           ^^^^^^^^^^^^^^^^^^^^^^^^^^^^^^^^^^^^
  File "C:\Users\91769\AppData\Local\Programs\Python\Python312\Lib\site-packages\fastapi\applications.py", line 269, in __call__
    await super().__call__(scope, receive, send)
  File "C:\Users\91769\AppData\Local\Programs\Python\Python312\Lib\site-packages\starlette\applications.py", line 124, in __call__
    await self.middleware_stack(scope, receive, send)
  File "C:\Users\91769\AppData\Local\Programs\Python\Python312\Lib\site-packages\starlette\middleware\errors.py", line 184, in __call__
    raise exc
  File "C:\Users\91769\AppData\Local\Programs\Python\Python312\Lib\site-packages\starlette\middleware\errors.py", line 162, in __call__
    await self.app(scope, receive, _send)
  File "C:\Users\91769\AppData\Local\Programs\Python\Python312\Lib\site-packages\starlette\exceptions.py", line 93, in __call__
    raise exc
  File "C:\Users\91769\AppData\Local\Programs\Python\Python312\Lib\site-packages\starlette\exceptions.py", line 82, in __call__
    await self.app(scope, receive, sender)
  File "C:\Users\91769\AppData\Local\Programs\Python\Python312\Lib\site-packages\fastapi\middleware\asyncexitstack.py", line 21, in __call__
    raise e
  File "C:\Users\91769\AppData\Local\Programs\Python\Python312\Lib\site-packages\fastapi\middleware\asyncexitstack.py", line 18, in __call__
    await self.app(scope, receive, send)
  File "C:\Users\91769\AppData\Local\Programs\Python\Python312\Lib\site-packages\starlette\routing.py", line 670, in __call__
    await route.handle(scope, receive, send)
  File "C:\Users\91769\AppData\Local\Programs\Python\Python312\Lib\site-packages\starlette\routing.py", line 266, in handle
    await self.app(scope, receive, send)
  File "C:\Users\91769\AppData\Local\Programs\Python\Python312\Lib\site-packages\starlette\routing.py", line 65, in app
    response = await func(request)
               ^^^^^^^^^^^^^^^^^^^
  File "C:\Users\91769\AppData\Local\Programs\Python\Python312\Lib\site-packages\fastapi\routing.py", line 227, in app
    raw_response = await run_endpoint_function(
                   ^^^^^^^^^^^^^^^^^^^^^^^^^^^^
  File "C:\Users\91769\AppData\Local\Programs\Python\Python312\Lib\site-packages\fastapi\routing.py", line 160, in run_endpoint_function
    return await dependant.call(**values)
           ^^^^^^^^^^^^^^^^^^^^^^^^^^^^^^
  File "C:\Users\91769\OneDrive\Desktop\Text-Summarization-NLP-Project\app.py", line 41, in predict_route
    raise e
  File "C:\Users\91769\OneDrive\Desktop\Text-Summarization-NLP-Project\app.py", line 38, in predict_route
    text = obj.predict(text)
           ^^^^^^^^^^^^^^^^^
  File "C:\Users\91769\OneDrive\Desktop\Text-Summarization-NLP-Project\src\textSummarizer\pipeline\prediction.py", line 13, in predict
    tokenizer = AutoTokenizer.from_pretrained(self.config.tokenizer_path)
                ^^^^^^^^^^^^^^^^^^^^^^^^^^^^^^^^^^^^^^^^^^^^^^^^^^^^^^^^^
  File "C:\Users\91769\AppData\Local\Programs\Python\Python312\Lib\site-packages\transformers\models\auto\tokenization_auto.py", line 826, in from_pretrained
    tokenizer_config = get_tokenizer_config(pretrained_model_name_or_path, **kwargs)
                       ^^^^^^^^^^^^^^^^^^^^^^^^^^^^^^^^^^^^^^^^^^^^^^^^^^^^^^^^^^^^^
  File "C:\Users\91769\AppData\Local\Programs\Python\Python312\Lib\site-packages\transformers\models\auto\tokenization_auto.py", line 658, in get_tokenizer_config
    resolved_config_file = cached_file(
                           ^^^^^^^^^^^^
  File "C:\Users\91769\AppData\Local\Programs\Python\Python312\Lib\site-packages\transformers\utils\hub.py", line 466, in cached_file
    raise EnvironmentError(
OSError: Incorrect path_or_model_id: 'artifacts/model_trainer/tokenizer'. Please provide either the path to a local folder or the repo_id of a model on the Hub.
[2024-07-13 20:04:17,667: INFO: common: yaml file: config\config.yaml loaded successfully]
[2024-07-13 20:04:17,669: INFO: common: yaml file: params.yaml loaded successfully]
[2024-07-13 20:04:17,670: INFO: common: created directory at: artifacts]
[2024-07-13 20:04:17,671: INFO: common: created directory at: artifacts/model_evaluation]
[2024-07-13 20:04:17,672: ERROR: h11_impl: Exception in ASGI application
]
Traceback (most recent call last):
  File "C:\Users\91769\AppData\Local\Programs\Python\Python312\Lib\site-packages\transformers\utils\hub.py", line 402, in cached_file
    resolved_file = hf_hub_download(
                    ^^^^^^^^^^^^^^^^
  File "C:\Users\91769\AppData\Local\Programs\Python\Python312\Lib\site-packages\huggingface_hub\utils\_validators.py", line 106, in _inner_fn
    validate_repo_id(arg_value)
  File "C:\Users\91769\AppData\Local\Programs\Python\Python312\Lib\site-packages\huggingface_hub\utils\_validators.py", line 154, in validate_repo_id
    raise HFValidationError(
huggingface_hub.errors.HFValidationError: Repo id must be in the form 'repo_name' or 'namespace/repo_name': 'artifacts/model_trainer/tokenizer'. Use `repo_type` argument if needed.

The above exception was the direct cause of the following exception:

Traceback (most recent call last):
  File "C:\Users\91769\AppData\Local\Programs\Python\Python312\Lib\site-packages\uvicorn\protocols\http\h11_impl.py", line 404, in run_asgi
    result = await app(  # type: ignore[func-returns-value]
             ^^^^^^^^^^^^^^^^^^^^^^^^^^^^^^^^^^^^^^^^^^^^^^
  File "C:\Users\91769\AppData\Local\Programs\Python\Python312\Lib\site-packages\uvicorn\middleware\proxy_headers.py", line 78, in __call__
    return await self.app(scope, receive, send)
           ^^^^^^^^^^^^^^^^^^^^^^^^^^^^^^^^^^^^
  File "C:\Users\91769\AppData\Local\Programs\Python\Python312\Lib\site-packages\fastapi\applications.py", line 269, in __call__
    await super().__call__(scope, receive, send)
  File "C:\Users\91769\AppData\Local\Programs\Python\Python312\Lib\site-packages\starlette\applications.py", line 124, in __call__
    await self.middleware_stack(scope, receive, send)
  File "C:\Users\91769\AppData\Local\Programs\Python\Python312\Lib\site-packages\starlette\middleware\errors.py", line 184, in __call__
    raise exc
  File "C:\Users\91769\AppData\Local\Programs\Python\Python312\Lib\site-packages\starlette\middleware\errors.py", line 162, in __call__
    await self.app(scope, receive, _send)
  File "C:\Users\91769\AppData\Local\Programs\Python\Python312\Lib\site-packages\starlette\exceptions.py", line 93, in __call__
    raise exc
  File "C:\Users\91769\AppData\Local\Programs\Python\Python312\Lib\site-packages\starlette\exceptions.py", line 82, in __call__
    await self.app(scope, receive, sender)
  File "C:\Users\91769\AppData\Local\Programs\Python\Python312\Lib\site-packages\fastapi\middleware\asyncexitstack.py", line 21, in __call__
    raise e
  File "C:\Users\91769\AppData\Local\Programs\Python\Python312\Lib\site-packages\fastapi\middleware\asyncexitstack.py", line 18, in __call__
    await self.app(scope, receive, send)
  File "C:\Users\91769\AppData\Local\Programs\Python\Python312\Lib\site-packages\starlette\routing.py", line 670, in __call__
    await route.handle(scope, receive, send)
  File "C:\Users\91769\AppData\Local\Programs\Python\Python312\Lib\site-packages\starlette\routing.py", line 266, in handle
    await self.app(scope, receive, send)
  File "C:\Users\91769\AppData\Local\Programs\Python\Python312\Lib\site-packages\starlette\routing.py", line 65, in app
    response = await func(request)
               ^^^^^^^^^^^^^^^^^^^
  File "C:\Users\91769\AppData\Local\Programs\Python\Python312\Lib\site-packages\fastapi\routing.py", line 227, in app
    raw_response = await run_endpoint_function(
                   ^^^^^^^^^^^^^^^^^^^^^^^^^^^^
  File "C:\Users\91769\AppData\Local\Programs\Python\Python312\Lib\site-packages\fastapi\routing.py", line 160, in run_endpoint_function
    return await dependant.call(**values)
           ^^^^^^^^^^^^^^^^^^^^^^^^^^^^^^
  File "C:\Users\91769\OneDrive\Desktop\Text-Summarization-NLP-Project\app.py", line 41, in predict_route
    raise e
  File "C:\Users\91769\OneDrive\Desktop\Text-Summarization-NLP-Project\app.py", line 38, in predict_route
    text = obj.predict(text)
           ^^^^^^^^^^^^^^^^^
  File "C:\Users\91769\OneDrive\Desktop\Text-Summarization-NLP-Project\src\textSummarizer\pipeline\prediction.py", line 13, in predict
    tokenizer = AutoTokenizer.from_pretrained(self.config.tokenizer_path)
                ^^^^^^^^^^^^^^^^^^^^^^^^^^^^^^^^^^^^^^^^^^^^^^^^^^^^^^^^^
  File "C:\Users\91769\AppData\Local\Programs\Python\Python312\Lib\site-packages\transformers\models\auto\tokenization_auto.py", line 826, in from_pretrained
    tokenizer_config = get_tokenizer_config(pretrained_model_name_or_path, **kwargs)
                       ^^^^^^^^^^^^^^^^^^^^^^^^^^^^^^^^^^^^^^^^^^^^^^^^^^^^^^^^^^^^^
  File "C:\Users\91769\AppData\Local\Programs\Python\Python312\Lib\site-packages\transformers\models\auto\tokenization_auto.py", line 658, in get_tokenizer_config
    resolved_config_file = cached_file(
                           ^^^^^^^^^^^^
  File "C:\Users\91769\AppData\Local\Programs\Python\Python312\Lib\site-packages\transformers\utils\hub.py", line 466, in cached_file
    raise EnvironmentError(
OSError: Incorrect path_or_model_id: 'artifacts/model_trainer/tokenizer'. Please provide either the path to a local folder or the repo_id of a model on the Hub.
[2024-07-13 20:04:19,048: INFO: common: yaml file: config\config.yaml loaded successfully]
[2024-07-13 20:04:19,051: INFO: common: yaml file: params.yaml loaded successfully]
[2024-07-13 20:04:19,052: INFO: common: created directory at: artifacts]
[2024-07-13 20:04:19,054: INFO: common: created directory at: artifacts/model_evaluation]
[2024-07-13 20:04:19,056: ERROR: h11_impl: Exception in ASGI application
]
Traceback (most recent call last):
  File "C:\Users\91769\AppData\Local\Programs\Python\Python312\Lib\site-packages\transformers\utils\hub.py", line 402, in cached_file
    resolved_file = hf_hub_download(
                    ^^^^^^^^^^^^^^^^
  File "C:\Users\91769\AppData\Local\Programs\Python\Python312\Lib\site-packages\huggingface_hub\utils\_validators.py", line 106, in _inner_fn
    validate_repo_id(arg_value)
  File "C:\Users\91769\AppData\Local\Programs\Python\Python312\Lib\site-packages\huggingface_hub\utils\_validators.py", line 154, in validate_repo_id
    raise HFValidationError(
huggingface_hub.errors.HFValidationError: Repo id must be in the form 'repo_name' or 'namespace/repo_name': 'artifacts/model_trainer/tokenizer'. Use `repo_type` argument if needed.

The above exception was the direct cause of the following exception:

Traceback (most recent call last):
  File "C:\Users\91769\AppData\Local\Programs\Python\Python312\Lib\site-packages\uvicorn\protocols\http\h11_impl.py", line 404, in run_asgi
    result = await app(  # type: ignore[func-returns-value]
             ^^^^^^^^^^^^^^^^^^^^^^^^^^^^^^^^^^^^^^^^^^^^^^
  File "C:\Users\91769\AppData\Local\Programs\Python\Python312\Lib\site-packages\uvicorn\middleware\proxy_headers.py", line 78, in __call__
    return await self.app(scope, receive, send)
           ^^^^^^^^^^^^^^^^^^^^^^^^^^^^^^^^^^^^
  File "C:\Users\91769\AppData\Local\Programs\Python\Python312\Lib\site-packages\fastapi\applications.py", line 269, in __call__
    await super().__call__(scope, receive, send)
  File "C:\Users\91769\AppData\Local\Programs\Python\Python312\Lib\site-packages\starlette\applications.py", line 124, in __call__
    await self.middleware_stack(scope, receive, send)
  File "C:\Users\91769\AppData\Local\Programs\Python\Python312\Lib\site-packages\starlette\middleware\errors.py", line 184, in __call__
    raise exc
  File "C:\Users\91769\AppData\Local\Programs\Python\Python312\Lib\site-packages\starlette\middleware\errors.py", line 162, in __call__
    await self.app(scope, receive, _send)
  File "C:\Users\91769\AppData\Local\Programs\Python\Python312\Lib\site-packages\starlette\exceptions.py", line 93, in __call__
    raise exc
  File "C:\Users\91769\AppData\Local\Programs\Python\Python312\Lib\site-packages\starlette\exceptions.py", line 82, in __call__
    await self.app(scope, receive, sender)
  File "C:\Users\91769\AppData\Local\Programs\Python\Python312\Lib\site-packages\fastapi\middleware\asyncexitstack.py", line 21, in __call__
    raise e
  File "C:\Users\91769\AppData\Local\Programs\Python\Python312\Lib\site-packages\fastapi\middleware\asyncexitstack.py", line 18, in __call__
    await self.app(scope, receive, send)
  File "C:\Users\91769\AppData\Local\Programs\Python\Python312\Lib\site-packages\starlette\routing.py", line 670, in __call__
    await route.handle(scope, receive, send)
  File "C:\Users\91769\AppData\Local\Programs\Python\Python312\Lib\site-packages\starlette\routing.py", line 266, in handle
    await self.app(scope, receive, send)
  File "C:\Users\91769\AppData\Local\Programs\Python\Python312\Lib\site-packages\starlette\routing.py", line 65, in app
    response = await func(request)
               ^^^^^^^^^^^^^^^^^^^
  File "C:\Users\91769\AppData\Local\Programs\Python\Python312\Lib\site-packages\fastapi\routing.py", line 227, in app
    raw_response = await run_endpoint_function(
                   ^^^^^^^^^^^^^^^^^^^^^^^^^^^^
  File "C:\Users\91769\AppData\Local\Programs\Python\Python312\Lib\site-packages\fastapi\routing.py", line 160, in run_endpoint_function
    return await dependant.call(**values)
           ^^^^^^^^^^^^^^^^^^^^^^^^^^^^^^
  File "C:\Users\91769\OneDrive\Desktop\Text-Summarization-NLP-Project\app.py", line 41, in predict_route
    raise e
  File "C:\Users\91769\OneDrive\Desktop\Text-Summarization-NLP-Project\app.py", line 38, in predict_route
    text = obj.predict(text)
           ^^^^^^^^^^^^^^^^^
  File "C:\Users\91769\OneDrive\Desktop\Text-Summarization-NLP-Project\src\textSummarizer\pipeline\prediction.py", line 13, in predict
    tokenizer = AutoTokenizer.from_pretrained(self.config.tokenizer_path)
                ^^^^^^^^^^^^^^^^^^^^^^^^^^^^^^^^^^^^^^^^^^^^^^^^^^^^^^^^^
  File "C:\Users\91769\AppData\Local\Programs\Python\Python312\Lib\site-packages\transformers\models\auto\tokenization_auto.py", line 826, in from_pretrained
    tokenizer_config = get_tokenizer_config(pretrained_model_name_or_path, **kwargs)
                       ^^^^^^^^^^^^^^^^^^^^^^^^^^^^^^^^^^^^^^^^^^^^^^^^^^^^^^^^^^^^^
  File "C:\Users\91769\AppData\Local\Programs\Python\Python312\Lib\site-packages\transformers\models\auto\tokenization_auto.py", line 658, in get_tokenizer_config
    resolved_config_file = cached_file(
                           ^^^^^^^^^^^^
  File "C:\Users\91769\AppData\Local\Programs\Python\Python312\Lib\site-packages\transformers\utils\hub.py", line 466, in cached_file
    raise EnvironmentError(
OSError: Incorrect path_or_model_id: 'artifacts/model_trainer/tokenizer'. Please provide either the path to a local folder or the repo_id of a model on the Hub.
[2024-07-13 20:05:34,877: INFO: server: Shutting down]
[2024-07-13 20:05:34,986: INFO: on: Waiting for application shutdown.]
[2024-07-13 20:05:34,987: INFO: on: Application shutdown complete.]
[2024-07-13 20:05:34,988: INFO: server: Finished server process [13368]]
[2024-07-19 21:47:02,197: INFO: server: Started server process [4284]]
[2024-07-19 21:47:02,198: INFO: on: Waiting for application startup.]
[2024-07-19 21:47:02,199: INFO: on: Application startup complete.]
[2024-07-19 21:47:02,200: INFO: server: Uvicorn running on http://0.0.0.0:8080 (Press CTRL+C to quit)]
[2024-07-19 21:47:10,766: INFO: server: Shutting down]
[2024-07-19 21:47:10,875: INFO: on: Waiting for application shutdown.]
[2024-07-19 21:47:10,876: INFO: on: Application shutdown complete.]
[2024-07-19 21:47:10,876: INFO: server: Finished server process [4284]]
